<?xml version="1.0" ?>
<robot name="ur">
  <link name="base_link"/>
  <joint name="base_link-pod_base_link" type="fixed">
    <parent link="base_link"/>
    <child link="pod_base_link"/>
    <origin rpy="0 0 0" xyz="0.0 0 0"/>
  </joint>

  <link name="pod_base_link">
  </link>
  
  <joint name="base_link-base_link_inertia" type="fixed">
    <parent link="base_link"/>
    <child link="base_link_inertia"/>
    <origin rpy="0 0 3.141592653589793" xyz="-0.05 -0.05 0.05"/>
  </joint>
  <link name="base_link_inertia">
    <visual>
      <origin rpy="0 0 3.141592653589793" xyz="0 0 0"/>
      <geometry>
        <mesh filename="package://Aurmar_description/meshes/ur16e/visual/base.dae"/>
      </geometry>
    </visual>
    <collision>
      <origin rpy="0 0 3.141592653589793" xyz="0 0 0"/>
      <geometry>
        <mesh filename="package://Aurmar_description/meshes/ur16e/collision/base.stl"/>
      </geometry>
    </collision>
    <inertial>
      <mass value="4.0"/>
      <origin rpy="0 0 0" xyz="0 0 0"/>
      <inertia ixx="0.0061063308908" ixy="0.0" ixz="0.0" iyy="0.0061063308908" iyz="0.0" izz="0.01125"/>
    </inertial>
  </link>
  <joint name="shoulder_pan_joint" type="revolute">
    <parent link="base_link_inertia"/>
    <child link="shoulder_link"/>
    <origin rpy="0 0 0" xyz="0 0 0.1807"/>
    <axis xyz="0 0 1"/>
    <limit effort="330.0" lower="-6.283185307179586" upper="6.283185307179586" velocity="2.0943951023931953"/>
    <dynamics damping="0" friction="0"/>
  </joint>
  <link name="shoulder_link">
    <visual>
      <origin rpy="0 0 3.141592653589793" xyz="0 0 0"/>
      <geometry>
        <mesh filename="meshes/ur16e/visual/shoulder.dae"/>
      </geometry>
    </visual>
    <collision>
      <origin rpy="0 0 3.141592653589793" xyz="0 0 0"/>
      <geometry>
        <mesh filename="meshes/ur16e/collision/shoulder.stl"/>
      </geometry>
    </collision>
    <inertial>
      <mass value="7.369"/>
      <origin rpy="0 0 0" xyz="0 0 0"/>
      <inertia ixx="0.029819260655624295" ixy="0.0" ixz="0.0" iyy="0.029819260655624295" iyz="0.0" izz="0.020725312499999995"/>
    </inertial>
  </link>
  <joint name="shoulder_lift_joint" type="revolute">
    <parent link="shoulder_link"/>
    <child link="upper_arm_link"/>
    <origin rpy="1.570796327 0 0" xyz="0 0 0"/>
    <axis xyz="0 0 1"/>
    <limit effort="330.0" lower="-6.283185307179586" upper="6.283185307179586" velocity="2.0943951023931953"/>
    <dynamics damping="0" friction="0"/>
  </joint>
  <link name="upper_arm_link">
    <visual>
      <origin rpy="1.5707963267948966 0 -1.5707963267948966" xyz="0 0 0.176"/>
      <geometry>
        <mesh filename="meshes/ur16e/visual/upperarm.dae"/>
      </geometry>
    </visual>
    <collision>
      <origin rpy="1.5707963267948966 0 -1.5707963267948966" xyz="0 0 0.176"/>
      <geometry>
        <mesh filename="meshes/ur16e/collision/upperarm.stl"/>
      </geometry>
    </collision>
    <inertial>
      <mass value="10.45"/>
      <origin rpy="0 1.5707963267948966 0" xyz="-0.2392 0.0 0.175"/>
      <inertia ixx="0.21399985623335657" ixy="0.0" ixz="0.0" iyy="0.21399985623335657" iyz="0.0" izz="0.029390624999999997"/>
    </inertial>
  </link>
  <joint name="elbow_joint" type="revolute">
    <parent link="upper_arm_link"/>
    <child link="forearm_link"/>
    <origin rpy="0 0 0" xyz="-0.4784 0 0"/>
    <axis xyz="0 0 1"/>
    <limit effort="150.0" lower="-6.283185307179586" upper="6.283185307179586" velocity="3.141592653589793"/>
    <dynamics damping="0" friction="0"/>
  </joint>
  <link name="forearm_link">
    <visual>
      <origin rpy="1.5707963267948966 0 -1.5707963267948966" xyz="0 0 0.04"/>
      <geometry>
        <mesh filename="meshes/ur16e/visual/forearm.dae"/>
      </geometry>
    </visual>
    <collision>
      <origin rpy="1.5707963267948966 0 -1.5707963267948966" xyz="0 0 0.04"/>
      <geometry>
        <mesh filename="meshes/ur16e/collision/forearm.stl"/>
      </geometry>
    </collision>
    <inertial>
      <mass value="4.321"/>
      <origin rpy="0 1.5707963267948966 0" xyz="-0.18 0.0 0.04"/>
      <inertia ixx="0.052743185152717496" ixy="0.0" ixz="0.0" iyy="0.052743185152717496" iyz="0.0" izz="0.012152812499999997"/>
    </inertial>
  </link>
  <joint name="wrist_1_joint" type="revolute">
    <parent link="forearm_link"/>
    <child link="wrist_1_link"/>
    <origin rpy="0 0 0" xyz="-0.36 0 0.17415"/>
    <axis xyz="0 0 1"/>
    <limit effort="56.0" lower="-6.283185307179586" upper="6.283185307179586" velocity="3.141592653589793"/>
    <dynamics damping="0" friction="0"/>
  </joint>
  <link name="wrist_1_link">
    <visual>
      <origin rpy="1.5707963267948966 0 0" xyz="0 0 -0.135"/>
      <geometry>
        <mesh filename="meshes/ur16e/visual/wrist1.dae"/>
      </geometry>
    </visual>
    <collision>
      <origin rpy="1.5707963267948966 0 0" xyz="0 0 -0.135"/>
      <geometry>
        <mesh filename="meshes/ur16e/collision/wrist1.stl"/>
      </geometry>
    </collision>
    <inertial>
      <mass value="2.18"/>
      <origin rpy="0 0 0" xyz="0 0 0"/>
      <inertia ixx="0.0056816227273499996" ixy="0.0" ixz="0.0" iyy="0.0056816227273499996" iyz="0.0" izz="0.00613125"/>
    </inertial>
  </link>
  <joint name="wrist_2_joint" type="revolute">
    <parent link="wrist_1_link"/>
    <child link="wrist_2_link"/>
    <origin rpy="1.570796327 0 0" xyz="0 -0.11985 -2.458164590756244e-11"/>
    <axis xyz="0 0 1"/>
    <limit effort="56.0" lower="-6.283185307179586" upper="6.283185307179586" velocity="3.141592653589793"/>
    <dynamics damping="0" friction="0"/>
  </joint>
  <link name="wrist_2_link">
    <visual>
      <origin rpy="0 0 0" xyz="0 0 -0.12"/>
      <geometry>
        <mesh filename="meshes/ur16e/visual/wrist2.dae"/>
      </geometry>
    </visual>
    <collision>
      <origin rpy="0 0 0" xyz="0 0 -0.12"/>
      <geometry>
        <mesh filename="meshes/ur16e/collision/wrist2.stl"/>
      </geometry>
    </collision>
    <inertial>
      <mass value="2.033"/>
      <origin rpy="0 0 0" xyz="0 0 0"/>
      <inertia ixx="0.0052985041305975" ixy="0.0" ixz="0.0" iyy="0.0052985041305975" iyz="0.0" izz="0.0057178125"/>
    </inertial>
  </link>
  <joint name="wrist_3_joint" type="revolute">
    <parent link="wrist_2_link"/>
    <child link="wrist_3_link"/>
    <origin rpy="1.570796326589793 3.141592653589793 3.141592653589793" xyz="0 0.11655 -2.390480459346185e-11"/>
    <axis xyz="0 0 1"/>
    <limit effort="56.0" lower="-6.283185307179586" upper="6.283185307179586" velocity="3.141592653589793"/>
    <dynamics damping="0" friction="0"/>
  </joint>
  <link name="wrist_3_link">
    <visual>
      <origin rpy="1.5707963267948966 0 0" xyz="0 0 -0.1168"/>
      <geometry>
        <mesh filename="meshes/ur16e/visual/wrist3.dae"/>
      </geometry>
    </visual>
    <collision>
      <origin rpy="1.5707963267948966 0 0" xyz="0 0 -0.1168"/>
      <geometry>
        <mesh filename="meshes/ur16e/collision/wrist3.stl"/>
      </geometry>
    </collision>
    <inertial>
      <mass value="0.907"/>
      <origin rpy="0 0 0" xyz="0.0 0.0 -0.025"/>
      <inertia ixx="0.0006481268240825001" ixy="0.0" ixz="0.0" iyy="0.0006481268240825001" iyz="0.0" izz="0.0009183374999999999"/>
    </inertial>
  </link>

  <!-- Suction Gripper -->
  <joint name="gripper_joint" type="fixed">
    <parent link="wrist_3_link"/>
    <child link="gripper_link"/>
    <origin rpy="0 0 4.7124" xyz="0 0 0"/>
  </joint>
  <link name="gripper_link">
    <inertial>
      <mass value="0.7"/>
      <origin rpy="0 0 0" xyz="0 0.0 0.055"/>
      <inertia ixx="0.000843" ixy="0.0" ixz="0.0" iyy="0.000843" iyz="0.0" izz="0.000519"/>
    </inertial>
    <visual>
      <origin rpy="0 0 0" xyz="0 0 0.095"/>
      <geometry>
        <mesh filename="robotiq_epick_visualization/meshes/visual/robotiq_epick.dae" scale="0.001 0.001 0.001"/>
      </geometry>
      <material name="">
        <color rgba="1 1 1 1"/>
      </material>
    </visual>
    <collision>
      <origin rpy="0 0 0" xyz="0 0 0.065"/>
      <geometry>
        <cylinder length="0.10" radius="0.0385"/>
      </geometry>
    </collision>
  </link>
  
  <joint name="rod_joint" type="fixed">
    <parent link="gripper_link"/>
    <child link="epick_rod"/>
    <origin rpy="0 0 0" xyz="0 0 0.13"/>
  </joint>
  <link name="epick_rod">
    <visual>
      <origin rpy="0 0 0" xyz="0 0 0"/>
      <geometry>
        <cylinder length="0.078" radius="0.0065"/>
      </geometry>
    </visual>
    <collision>
      <origin rpy="0 0 0" xyz="0 0 0"/>
      <geometry>
        <cylinder length="0.078" radius="0.0065"/>
      </geometry>
    </collision>
    <inertial>
      <origin rpy="0 0 0" xyz="0 0 0"/>
      <mass value="0.070"/>
      <inertia ixx="3.6e-05" ixy="0" ixz="0" iyy="3.6e-05" iyz="0" izz="1e-06"/>
    </inertial>
  </link>
  
  <joint name="eef_hand_joint" type="prismatic">
    <parent link="epick_rod"/>
    <child link="epick_end_effector"/>
    <axis xyz="0 0 1"/>
    <origin rpy="0 0 0" xyz="0 0 0.053"/>
    <dynamics damping="0.0" friction="1.2"/>
    <limit effort="1000.0" lower="0.0" upper="0.0" velocity="1"/>
  </joint>
  <link name="epick_end_effector">
    <visual>
      <origin rpy="0 0 0" xyz="0 0 0"/>
      <geometry>
        <cylinder length="0.01" radius="0.02"/>
      </geometry>
    </visual>
    <collision>
      <origin rpy="0 0 0" xyz="0 0 0"/>
      <geometry>
        <cylinder length="0.01" radius="0.02"/>
      </geometry>
    </collision>
    <inertial>
      <origin rpy="0 0 0" xyz="0 0 0"/>
      <mass value="0.01"/>
      <inertia ixx="1e-06" ixy="0" ixz="0" iyy="1e-06" iyz="0" izz="2e-06"/>
    </inertial>
  </link>
  <joint name="ee_fixed_joint" type="fixed">
    <parent link="epick_end_effector"/>
    <child link="ee_link"/>
    <origin rpy="0 -1.57 -3.14" xyz="0.0 0.0 -0.005"/> 
  </joint>
  <link name="ee_link"/>
</robot>